Workbook

Sheet Lesehinweise
A1: Regelprüfung GBU EN 81-20 (Fragebogen) – offene Regeln
A2: Regelwerk 81-20-mf-2026.10 · Stand 16.09.2026 · 354 offene Regeln in 95 Gefährdungen, davon 94 Auffangregeln (Kein Risiko), 260 fachliche Regeln und 120 nach dem externen Prüfbericht geänderte Regeln.
A4: Zweite Fassung: Der externe Prüfbericht zur ersten Fassung ist eingearbeitet. Blatt „Prüfbericht“ zeigt je Befund, ob er zutrifft und was geändert wurde; die geänderten Regeln sind in den Bereichsblättern orange markiert (Status „offen – geändert“).
A5: Der Katalog „Bestand nach DIN EN 81-80“ ist aus diesem Katalog abgeleitet – eine Freigabe hier gilt dort automatisch. Das ist zulässig, weil der Generator Regeln, Gefährdungen und Anwendbarkeit dort unverändert übernimmt und bei jeder Abweichung abbricht. Die Kopfzeile nennt die zugehörigen EN-81-80-Punkte bzw. „nicht im Bestandskatalog“.
A6: Dritte Fassung (16.09.2026): Regel-IDs sind jetzt dauerhaft – eine ID bezeichnet immer denselben Sachverhalt; neue Sachverhalte bekommen neue Nummern (deshalb Lücken). Die Prüfliste v2 ist damit überholt, bitte nur diese Datei ausfüllen. „Rev.“ im Status zählt inhaltliche Änderungen seit der ersten Fassung.
A7: Baujahr-Annahmen (Festlegung 07.09., bestätigt 16.09.2026): Ab dem genannten Baujahr gilt ein Ausstattungsmerkmal als vorhanden, solange niemand widerspricht; im Bericht steht dann „angenommen“. Blatt „Fragen“, Spalte „Annahme ab Baujahr“ zeigt, welche Fragen betroffen sind.
A9: So wird entschieden
A10: 1. Je Erhebungsbereich ein Blatt, darin je Gefährdung ein Block. Die blaue Kopfzeile nennt Titel, Faktor, betroffene Personen, Bewertungslogik, wann die Gefährdung überhaupt bewertet wird (Anwendbarkeit), welche Fragen vorher beantwortet sein müssen (Pflichtfragen), EN-81-80-Bezug und Quellen.
A11: 2. Passt der ganze Block: in der Kopfzeile „Freigeben“ wählen – das gilt für alle offenen Regeln der Gefährdung, einschließlich der Auffangregel.
A12: 3. Passt eine einzelne Regel nicht: in ihrer Zeile „Ändern“ oder „Streichen“ wählen und in „Korrektur“ sagen, was gelten soll. Ohne Korrektur wird die Zelle rot. Die Einzelentscheidung geht der Sammelentscheidung vor.
A13: 4. Leer lassen = noch nicht entschieden. Blockweise arbeiten und zwischendurch zurückgeben ist möglich.
A14: 5. Blatt „Prüfbericht“: Bei den offenen Punkten (Spalte „Entscheidung nötig“) bitte Übernehmen / Ablehnen / Später wählen und ggf. kommentieren.
... A27: Rückweg (technisch): python3 apply_mf_regelpruefung.py → python3 gen_mf_catalog.py → python3 gen_en8180_catalog.py → App-Assets erneuern → Engine neu seeden. Freigaben sind an den Regelinhalt gebunden: Wird eine Regel später geändert, fällt sie automatisch wieder auf „offen“.

Sheet Übersicht
A1: Erhebungsbereich | B1: Blatt | C1: Gefährdungen | D1: offene Regeln | E1: davon Auffang | F1: davon geändert (Prüfbericht) | G1: entschieden | H1: Freigeben | I1: Ändern | J1: Streichen | K1: Korrektur fehlt | L1: Fortschritt | M1: fachlich freigabereif
A2: Z – Zugang zum Triebwerks-/Steuerungsraum | B2: Z Zugang | C2: 9 | D2: 35 | E2: 9 | F2: 7 | G2: =COUNTIF('Z Zugang'!$L$2:$L$49,"?*") -> 0 | H2: =COUNTIF('Z Zugang'!$L$2:$L$49,"Freigeben") -> 0 | I2: =COUNTIF('Z Zugang'!$L$2:$L$49,"Ändern") -> 0 | J2: =COUNTIF('Z Zugang'!$L$2:$L$49,"Streichen") -> 0 | K2: =COUNTIFS('Z Zugang'!$J$2:$J$49,"Ändern",'Z Zugang'!$K$2:$K$49,"")+COUNTIFS('Z Zugang'!$J$2:$J$49,"Streichen",'Z Zugang'!$K$2:$K$49,"") -> 0 | L2: =IF(D2=0,"",G2/D2) -> 0 | M2: =IF(AND(H2=D2,K2=0),"ja","nein") -> nein
A3: M – Triebwerks-/Maschinenraum und Steuerung | B3: M Triebwerksraum | C3: 20 | D3: 74 | E3: 20 | F3: 9 | G3: =COUNTIF('M Triebwerksraum'!$L$2:$L$98,"?*") -> 0 | H3: =COUNTIF('M Triebwerksraum'!$L$2:$L$98,"Freigeben") -> 0 | I3: =COUNTIF('M Triebwerksraum'!$L$2:$L$98,"Ändern") -> 0 | J3: =COUNTIF('M Triebwerksraum'!$L$2:$L$98,"Streichen") -> 0 | K3: =COUNTIFS('M Triebwerksraum'!$J$2:$J$98,"Ändern",'M Triebwerksraum'!$K$2:$K$98,"")+COUNTIFS('M Triebwerksraum'!$J$2:$J$98,"Streichen",'M Triebwerksraum'!$K$2:$K$98,"") -> 0 | L3: =IF(D3=0,"",G3/D3) -> 0 | M3: =IF(AND(H3=D3,K3=0),"ja","nein") -> nein
A4: T – Schachttüren und Fahrkorbtür | B4: T Türen | C4: 6 | D4: 27 | E4: 6 | F4: 15 | G4: =COUNTIF('T Türen'!$L$2:$L$36,"?*") -> 0 | H4: =COUNTIF('T Türen'!$L$2:$L$36,"Freigeben") -> 0 | I4: =COUNTIF('T Türen'!$L$2:$L$36,"Ändern") -> 0 | J4: =COUNTIF('T Türen'!$L$2:$L$36,"Streichen") -> 0 | K4: =COUNTIFS('T Türen'!$J$2:$J$36,"Ändern",'T Türen'!$K$2:$K$36,"")+COUNTIFS('T Türen'!$J$2:$J$36,"Streichen",'T Türen'!$K$2:$K$36,"") -> 0 | L4: =IF(D4=0,"",G4/D4) -> 0 | M4: =IF(AND(H4=D4,K4=0),"ja","nein") -> nein
A5: K – Fahrkorb | B5: K Fahrkorb | C5: 14 | D5: 54 | E5: 14 | F5: 19 | G5: =COUNTIF('K Fahrkorb'!$L$2:$L$70,"?*") -> 0 | H5: =COUNTIF('K Fahrkorb'!$L$2:$L$70,"Freigeben") -> 0 | I5: =COUNTIF('K Fahrkorb'!$L$2:$L$70,"Ändern") -> 0 | J5: =COUNTIF('K Fahrkorb'!$L$2:$L$70,"Streichen") -> 0 | K5: =COUNTIFS('K Fahrkorb'!$J$2:$J$70,"Ändern",'K Fahrkorb'!$K$2:$K$70,"")+COUNTIFS('K Fahrkorb'!$J$2:$J$70,"Streichen",'K Fahrkorb'!$K$2:$K$70,"") -> 0 | L5: =IF(D5=0,"",G5/D5) -> 0 | M5: =IF(AND(H5=D5,K5=0),"ja","nein") -> nein
A6: F – Fahrkorbdach und Schachtkopf | B6: F Fahrkorbdach | C6: 9 | D6: 34 | E6: 9 | F6: 15 | G6: =COUNTIF('F Fahrkorbdach'!$L$2:$L$47,"?*") -> 0 | H6: =COUNTIF('F Fahrkorbdach'!$L$2:$L$47,"Freigeben") -> 0 | I6: =COUNTIF('F Fahrkorbdach'!$L$2:$L$47,"Ändern") -> 0 | J6: =COUNTIF('F Fahrkorbdach'!$L$2:$L$47,"Streichen") -> 0 | K6: =COUNTIFS('F Fahrkorbdach'!$J$2:$J$47,"Ändern",'F Fahrkorbdach'!$K$2:$K$47,"")+COUNTIFS('F Fahrkorbdach'!$J$2:$J$47,"Streichen",'F Fahrkorbdach'!$K$2:$K$47,"") -> 0 | L6: =IF(D6=0,"",G6/D6) -> 0 | M6: =IF(AND(H6=D6,K6=0),"ja","nein") -> nein
A7: S – Schacht | B7: S Schacht | C7: 7 | D7: 25 | E7: 7 | F7: 4 | G7: =COUNTIF('S Schacht'!$L$2:$L$35,"?*") -> 0 | H7: =COUNTIF('S Schacht'!$L$2:$L$35,"Freigeben") -> 0 | I7: =COUNTIF('S Schacht'!$L$2:$L$35,"Ändern") -> 0 | J7: =COUNTIF('S Schacht'!$L$2:$L$35,"Streichen") -> 0 | K7: =COUNTIFS('S Schacht'!$J$2:$J$35,"Ändern",'S Schacht'!$K$2:$K$35,"")+COUNTIFS('S Schacht'!$J$2:$J$35,"Streichen",'S Schacht'!$K$2:$K$35,"") -> 0 | L7: =IF(D7=0,"",G7/D7) -> 0 | M7: =IF(AND(H7=D7,K7=0),"ja","nein") -> nein
A8: G – Schachtgrube | B8: G Schachtgrube | C8: 8 | D8: 34 | E8: 8 | F8: 10 | G8: =COUNTIF('G Schachtgrube'!$L$2:$L$46,"?*") -> 0 | H8: =COUNTIF('G Schachtgrube'!$L$2:$L$46,"Freigeben") -> 0 | I8: =COUNTIF('G Schachtgrube'!$L$2:$L$46,"Ändern") -> 0 | J8: =COUNTIF('G Schachtgrube'!$L$2:$L$46,"Streichen") -> 0 | K8: =COUNTIFS('G Schachtgrube'!$J$2:$J$46,"Ändern",'G Schachtgrube'!$K$2:$K$46,"")+COUNTIFS('G Schachtgrube'!$J$2:$J$46,"Streichen",'G Schachtgrube'!$K$2:$K$46,"") -> 0 | L8: =IF(D8=0,"",G8/D8) -> 0 | M8: =IF(AND(H8=D8,K8=0),"ja","nein") -> nein
A9: U – Umfeld, Gebäude und Nutzung | B9: U Umfeld | C9: 15 | D9: 54 | E9: 15 | F9: 33 | G9: =COUNTIF('U Umfeld'!$L$2:$L$75,"?*") -> 0 | H9: =COUNTIF('U Umfeld'!$L$2:$L$75,"Freigeben") -> 0 | I9: =COUNTIF('U Umfeld'!$L$2:$L$75,"Ändern") -> 0 | J9: =COUNTIF('U Umfeld'!$L$2:$L$75,"Streichen") -> 0 | K9: =COUNTIFS('U Umfeld'!$J$2:$J$75,"Ändern",'U Umfeld'!$K$2:$K$75,"")+COUNTIFS('U Umfeld'!$J$2:$J$75,"Streichen",'U Umfeld'!$K$2:$K$75,"") -> 0 | L9: =IF(D9=0,"",G9/D9) -> 0 | M9: =IF(AND(H9=D9,K9=0),"ja","nein") -> nein
A10: SF – Sonderfunktionen | B10: SF Sonderfunktionen | C10: 1 | D10: 1 | E10: 1 | F10: 0 | G10: =COUNTIF('SF Sonderfunktionen'!$L$2:$L$13,"?*") -> 0 | H10: =COUNTIF('SF Sonderfunktionen'!$L$2:$L$13,"Freigeben") -> 0 | I10: =COUNTIF('SF Sonderfunktionen'!$L$2:$L$13,"Ändern") -> 0 | J10: =COUNTIF('SF Sonderfunktionen'!$L$2:$L$13,"Streichen") -> 0 | K10: =COUNTIFS('SF Sonderfunktionen'!$J$2:$J$13,"Ändern",'SF Sonderfunktionen'!$K$2:$K$13,"")+COUNTIFS('SF Sonderfunktionen'!$J$2:$J$13,"Streichen",'SF Sonderfunktionen'!$K$2:$K$13,"") -> 0 | L10: =IF(D10=0,"",G10/D10) -> 0 | M10: =IF(AND(H10=D10,K10=0),"ja","nein") -> nein
A11: D – Unterlagen und Betreiberorganisation | B11: D Unterlagen | C11: 6 | D11: 16 | E11: 5 | F11: 8 | G11: =COUNTIF('D Unterlagen'!$L$2:$L$31,"?*") -> 0 | H11: =COUNTIF('D Unterlagen'!$L$2:$L$31,"Freigeben") -> 0 | I11: =COUNTIF('D Unterlagen'!$L$2:$L$31,"Ändern") -> 0 | J11: =COUNTIF('D Unterlagen'!$L$2:$L$31,"Streichen") -> 0 | K11: =COUNTIFS('D Unterlagen'!$J$2:$J$31,"Ändern",'D Unterlagen'!$K$2:$K$31,"")+COUNTIFS('D Unterlagen'!$J$2:$J$31,"Streichen",'D Unterlagen'!$K$2:$K$31,"") -> 0 | L11: =IF(D11=0,"",G11/D11) -> 0 | M11: =IF(AND(H11=D11,K11=0),"ja","nein") -> nein
A12: Summe | C12: =SUM(C2:C11) -> 95 | D12: =SUM(D2:D11) -> 354 | E12: =SUM(E2:E11) -> 94 | F12: =SUM(F2:F11) -> 120 | G12: =SUM(G2:G11) -> 0 | H12: =SUM(H2:H11) -> 0 | I12: =SUM(I2:I11) -> 0 | J12: =SUM(J2:J11) -> 0 | K12: =SUM(K2:K11) -> 0 | L12: =IF(D12=0,"",G12/D12) -> 0 | M12: =IF(AND(H12=D12,K12=0),"ja","nein") -> nein
A14: „entschieden“ zählt jede offene Regel mit wirksamer Entscheidung – der eigenen oder der Sammelfreigabe ihrer Gefährdung. „fachlich freigabereif“ = jede offene Regel ist freigegeben und keine Korrektur fehlt; „Ändern“/„Streichen“ bleiben offen, bis der Katalog angepasst und erneut vorgelegt ist.

Sheet Prüfbericht
A1: ID | B1: Priorität | C1: Bereich / Regeln | D1: Bewertung | E1: Begründung / Beleg | F1: Umsetzung | G1: Entscheidung nötig | H1: Deine Entscheidung | I1: Kommentar
A2: Runde 1 – externer Prüfbericht vom 15.09.2026 (Stand der Umsetzung 16.09.2026)
A3: B01 | B3: Kritisch | C3: Anwendbarkeit / Gates | D3: teilweise | E3: Der Katalog hat Anwendbarkeitsfilter (Aufzugsart, Antrieb, Maschinen- und Rollenraum, gemeinsamer Schacht, Gegengewicht, BMA/RWA/Sprinkler/Brandfallsteuerung, Feuerwehraufzug, Nutzung durch mobilitätseingeschränkte Personen) und Sichtbarkeitsregeln. Die alte Prüfliste hat sie nicht angezeigt. | F3: Übernommen (Empfehlung 16.09.): Antwort „nicht anwendbar“ mit Begründung, getrennt von „unbekannt“ – kommt mit der App-Runde (Antwortmodell).
A4: B02 | B4: Kritisch | C4: Referenzintegrität | D4: bestätigt | E4: Blatt „Fragen“ enthielt nur die Fragen der offenen Regeln. | F4: Behoben: Das Blatt enthält alle Fragen der gezeigten Gefährdungen mit Sichtbarkeit und Pflicht.
A5: B03 | B5: Kritisch | C5: MF-G07 | D5: bestätigt | E5: TRBS 3121 Anh. 1 Nr. 2: 2 m über Schachtgrubensohle; die 2,50 m über der untersten Haltestelle gehören zu Nr. 3 (Nachbaraufzug). | F5: Korrigiert: MF-G07-R1 (Maß), MF-G07-R4 (Warnhinweis als organisatorische Maßnahme).
A6: B04 | B6: Kritisch | C6: MF-G04 | D6: bestätigt | E6: TRBS 3121 Anh. 1 Nr. 6: Risiko hoch bei TRA-200-Anlagen bis Baujahr 1992 (Abstiegseinrichtung erst ab 1,5 m Grubentiefe gefordert), niedrig bei TRA 200 ab 1992 und EN 81-1/2. | F6: Umgesetzt 16.09. nach Empfehlung: zuerst die Zugangsart (11.7 separate Grubenzugangstür), Leiterfragen nur bei Zugang über Leiter. Keine pauschale Baujahr-Korrektur.
A7: B05 | B7: Kritisch | C7: MF-S01 | D7: bestätigt | E7: TRBS 3121 Anh. 1 Nr. 8: mind. 50 lx im Arbeitsbereich auf dem Fahrkorbdach und in der Grube; Risiko niedrig, wenn TRA 200 / EN 81-1/2 erfüllt. | F7: Korrigiert: Frage 10.1a auf 50 lx über dem Fahrkorbdach; neue Frage 10.1c (Altnorm erfüllt → Niedrig). Die Grube hatte 50 lx bereits (11.2a).
A8: B06 | B8: Kritisch | C8: MF-T04 | D8: bestätigt | E8: Bei „Höchste Stufe“ hat die Nicht-VSG-Regel die Drahtglas-Regel immer übersteuert. | F8: Korrigiert: MF-T04-R1 nimmt Drahtglas aus; neue Frage 7.8a und Regel für beschädigtes/loses Glas; 7.8 fragt nur noch die Glasart.
A9: B07 | B9: Kritisch | C9: MF-T06 | D9: bestätigt | E9: TRBS 3121 Anh. 1 Nr. 14 c): Lichtgitter statt Fahrkorbtür nur bei Lastenaufzügen mit ausschließlich eingewiesenem Nutzerkreis. | F9: Korrigiert: Mittel nur bei Nutzungsart Lastenaufzug und Frage 8.9b = Ja; sonst neue Regel Hoch.
A10: B08 | B10: Kritisch | C10: MF-K05 | D10: teilweise | E10: TRBS 3121 Anh. 1 Nr. 19 nennt die Maßnahmen als Alternativen und für Altanlagen niedrig bis mittel je nach Nutzerkreis. Die Verschärfung (beide Verriegelungen) ist deine Entscheidung K-K04 vom 02.09.2026. | F10: Umgesetzt 16.09.: TRBS-Alternative (eine Verriegelung) = Niedrig; ohne Maßnahme Mittel; Hoch nur bei Kindern und als EIGENER STANDARD gekennzeichnet; Kein Risiko weiter nur mit beiden (K-K04).
A11: B09 | B11: Kritisch | C11: Gebäudeschnittstellen | D11: nicht zutreffend | E11: MF-K08 (4.11 Brandfallsteuerung gefordert), MF-U09 (BMA vorhanden), MF-U10 (Entrauchung vorhanden), MF-U11 (Sprinkler vorhanden) und MF-SF01 (Feuerwehraufzug) haben Anwendbarkeitsfilter. Die alte Prüfliste hat sie nur nicht angezeigt. | F11: Filter sind jetzt in der Kopfzeile sichtbar.
A12: B10 | B12: Kritisch | C12: MF-K10 | D12: teilweise | E12: Der Filter 4.9 (Nutzung durch mobilitätseingeschränkte Personen) existiert. Eine Anforderung aus Genehmigung/Nutzung wird nicht abgefragt; das Maß 1,00 × 1,25 m ist fest vorgegeben. | F12: Umgesetzt 16.09.: neue Frage 4.9a „barrierefreie Ausführung gefordert“ löst die Prüfung ebenfalls aus; Maß mit Fahrkorbtyp und Normausgabe.
A13: B11 | B13: Kritisch | C13: F02/F05/F07/M10/S05 | D13: bestätigt | E13: Unwirksame oder widersprüchliche Maßnahmen. | F13: Korrigiert: MF-F02-R1/R2, MF-F05-R2, MF-F07-R1, MF-M10-R2 (inkl. Schreibfehler), MF-S05-R2.
A14: B12 | B14: Kritisch | C14: MF-M13 | D14: bestätigt | E14: Bei fehlendem Absperrventil wurde nur Zugänglichkeit/Kennzeichnung verlangt. | F14: Korrigiert: MF-M13-R4 verlangt den Einbau; bis dahin gesicherter Fahrkorb.
... A27: H11 | B27: Hoch | C27: Maßnahmenlücken | D27: bestätigt | E27: 10 Regeln ohne Sofort- oder Folgemaßnahme; die eigene Vorprüfung hatte nur eine gefunden. | F27: Korrigiert; der Smoke-Test prüft das künftig für den ganzen Katalog.
A28: H12 | B28: Hoch | C28: T/O-Kennzeichnung | D28: bestätigt | E28: Systematische Ursache: Die Art hing an der Zeitlage (sofort = O, mittelfristig = T). | F28: Umgesetzt: Art aus dem Inhalt, gemischte eigene Texte bereinigt. „P“ (personenbezogen) kommt mit der App-Runde (Schema, Datenbank, App). Bitte Blatt „Maßnahmenarten“ gegenlesen. | G28: ja
A29: H13 | B29: Hoch | C29: Quellenstand | D29: bestätigt | E29: Die geltende TRBS 3121 (GMBl 2025 S. 691) gliedert den Haupttext nur bis Abschnitt 3. | F29: Korrigiert: Z09 → 3.1.3/3.7.3, M15 → 3.7.3, D01 → 3.6/3.2 Nr. 6, D03 → 3.4.1, D05 → 3.3, U12 → 3.4.2.
A30: H14 | B30: Hoch | C30: Formelwerte | D30: bestätigt | E30: Formeln ohne gespeicherte Ergebnisse. | F30: Behoben: Die Datei wird vor der Ausgabe neu berechnet.
A31: H15 | B31: Hoch | C31: MF-F04 | D31: bestätigt | E31: Die Schutzeinrichtung wirkt, es fehlt nur die Kennzeichnung. | F31: Korrigiert: MF-F04-R2 Mittel statt Hoch.
A32: H16 | B32: Hoch | C32: MF-K11 | D32: bestätigt | E32: Videoüberwachung als pauschale Abhilfe. | F32: Korrigiert: MF-K11-R3 nach DIN EN 81-71; weitere Maßnahmen nach Ursachenanalyse.
A33: M01 | B33: Mittel | C33: Hilfetexte | D33: bestätigt | E33: Nur 20 von 289 Fragen haben einen Hilfetext. | F33: Teilweise umgesetzt 16.09.: 37 sicherheitskritische Fragen haben jetzt einen Prüfhinweis (65 von 294 insgesamt). Rest folgt.
A34: M02 | B34: Mittel | C34: Ergebnisdokumentation | D34: teilweise | E34: Die App führt Maßnahmen je Befund mit Verfolgung; das Restrisiko fehlt (siehe B14). | F34: Siehe B14.
A35: M03 | B35: Mittel | C35: Normrückverfolgung | D35: teilweise | E35: Die EN-81-80-Zuordnung liegt je Punkt vor (en8180_map, GBU_EN8180_Zuordnung.xlsx); die Prüfliste zeigte nur ja/nein. | F35: Behoben: Die Kopfzeile nennt die EN-81-80-Punkte mit Abschnitt.
A36: M04 | B36: Mittel | C36: Schreibfehler | D36: bestätigt | E36: „Motrorregelung“, „Machinenrahmen“, „nachrüste“, „Eignung ,“. | F36: Korrigiert (zentrale Textkorrektur beim Einlesen der App-Maßnahmen).
A37: M05 | B37: Mittel | C37: Blattschutz | D37: bestätigt | E37: Blätter ungeschützt. | F37: Behoben: Blattschutz ohne Kennwort; nur Entscheidungs- und Korrekturzellen sind offen, Filter bleiben nutzbar.
A38: N01 | B38: Niedrig | C38: Darstellung | D38: teilweise | E38: Sehr textdicht. | F38: Teilweise: Geänderte Regeln sind farbig markiert und filterbar (Status „offen – geändert“).
A39: Runde 2 – zweite Prüfung vom 16.09.2026
A40: P2-1 | B40: Hoch | C40: MF-T06 | D40: bestätigt | E40: Scherengitter-Regel (Prio 200) verdrängte die Hoch-Regel für Ersatzlösungen ohne Voraussetzung; „keine Schließkantensicherung“ war bei mobilitätseingeschränkten Nutzern günstiger als die Einzel-Lichtschranke. | F40: Umgesetzt: Licht- und Scherengitter laufen über dieselbe Voraussetzung (Lastenaufzug, nur Eingewiesene), sonst Hoch; neue Regel „keine Schließkantensicherung + PmeM = Hoch“; Maßnahme in R1 begrenzt. Ein Monotonie-Test prüft, dass weniger Schutz nie günstiger bewertet wird.
A41: P2-2 | B41: Hoch | C41: Baujahr-Annahmen | D41: teilweise | E41: Ein Baujahr begründet eine Erwartung, keinen Nachweis. | F41: Entscheidung Arne 16.09.2026: Annahmen bleiben wie am 07.09. festgelegt (widerlegbar, im Bericht als „angenommen“ ausgewiesen). Behoben: 1.24 Baujahr und 1.29 Konformitätsnachweis stehen jetzt im Blatt „Fragen“, dazu je Frage die Annahme.
A42: P2-3 | B42: Hoch | C42: K02 / U06 / F03 / G08 / 8.4 | D42: bestätigt | E42: Risikominderung ohne nachgewiesene Schutzwirkung. | F42: Umgesetzt: K02 beleuchteter Taster = Niedrig statt Kein Risiko; U06 neue Frage 15.25b (Ex-Schutz umgesetzt und geprüft), sonst Hoch; F03/G08 neue Fragen 9.6b/11.14b (Abschaltung geprüft), sonst Mittel. 8.4 ist bewusst nur Dokumentation (für den Cyber-Fragebogen) und jetzt so beschriftet.
A43: P2-4 | B43: Hoch | C43: MF-G04 / MF-T04 | D43: bestätigt | E43: Leiter wurde auch bei ebenerdigem Grubenzugang bewertet; Einzugsschutz für Schiebetüren auch bei Drehtüren abgefragt. | F43: Umgesetzt: Zugangsart zuerst (11.7), Leiter nur bei Leiterzugang; neue Frage 7.9a (kraftbetätigte Schiebetür), Einzugsschutz nur dann.
A44: P2-5 | B44: Hoch | C44: MF-M08 / MF-K13 / MF-K14 / MF-K12 | D44: bestätigt | E44: Indirekte Hydraulikaufzüge wurden wie Treibscheibenaufzüge behandelt; „SR-Modul ausbauen“ ist keine Standardalternative. | F44: Umgesetzt: Betriebsbremse, Wellenlagerung und Sturz nach oben nur bei Treibscheiben-/Trommelantrieb; K12-R1-Maßnahme mit anlagenspezifischer Prüfung.
A45: P2-6 | B45: Hoch | C45: Regelkennungen | D45: bestätigt | E45: Zwischen v1 und v2 wurden Codes neu belegt (z. B. MF-T04-R3). | F45: Umgesetzt: Regel-IDs hängen jetzt am Sachverhalt (Bedingung + Anwendbarkeit) und werden nie neu vergeben (mf_content/regel_ids.json, Basis v1). Revision je Regel; die Freigabe ist zusätzlich an Gefährdungslogik, abhängige Fragen und Maßnahmentexte gebunden. Die Prüfliste v2 ist damit überholt.
A46: P2-7 | B46: Mittel | C46: Bestandskatalog | D46: bestätigt | E46: 13 Gefährdungen fehlten im Bestandskatalog. | F46: Entscheidung Arne 16.09.2026: K12, K14 (TRBS 3121 Nr. 16) und die Betreiberpflichten Z01, Z04, Z05, Z06, Z08, Z09, M16, M19, S06, F08 aufgenommen; F02 bleibt als reiner EN-81-20-Konstruktionspunkt draußen. Die Freigabe gilt weiter für beide Kataloge, weil der Generator identische Regeln, Gefährdungen und Anwendbarkeit erzwingt.
A47: P2-8 | B47: Mittel | C47: Maßnahmen präzisieren | D47: teilweise | E47: „Vorsicht“ ist keine Schutzmaßnahme; Verantwortlichkeit, Termin und Wirksamkeitsnachweis fehlen. | F47: Umgesetzt: 12 unkonkrete Sofortmaßnahmen ersetzt. Verantwortlich, Frist und Wirksamkeit gehören an den Befund in der App (Maßnahmenverfolgung) – App-Runde.
A48: P2-9 | B48: Mittel | C48: T/O/P | D48: teilweise | E48: Gemischte Maßnahmen, P fehlt. | F48: Eigene gemischte Texte (Leuchten + Schutzhelm) bereinigt; P kommt mit der App-Runde.
A49: P2-10 | B49: Mittel | C49: Hilfetexte | D49: bestätigt | E49: Nur wenige Fragen mit echtem Prüfhinweis. | F49: 37 sicherheitskritische Fragen ergänzt (Prüfmethode, Abgrenzung, Nachweis) – bitte im Blatt „Fragen“ gegenlesen. | G49: ja
A50: P2-11 | B50: Niedrig | C50: Freigabereife | D50: bestätigt | E50: 100 % entschieden ist nicht gleich freigabereif. | F50: Übersicht hat die Spalte „freigabereif“ (alles entschieden, alles Freigeben, keine fehlende Korrektur).

Sheet Z Zugang
A1: Art | B1: Code | C1: Prio | D1: Gefährdung / Bedingung | E1: Stufe | F1: Sofortmaßnahme | G1: Mittelfristige Maßnahme | H1: Hinweis / Quelle | I1: Status | J1: Entscheidung | K1: Korrektur | L1: wirksam
A2: Gefährdung | B2: MF-Z01 | D2: Unzureichende Beleuchtung an den Zuwegen zum Triebwerks-/Steuerungsraum Faktor: Gefährdung durch Arbeitsumgebungsbedingungen (unzureichende Beleuchtung) Betroffen: Beauftragte Person, Wartungspersonal Bewertungslogik: Höchste Stufe – alle zutreffenden Regeln zählen, maßgeblich ist die HÖCHSTE STUFE; Maßnahmen aller Treffer werden übernommen. Bewertet, wenn: immer Pflichtfragen: 5.1, 5.2 (wenn [5.1] = Ja), 5.2a (wenn [5.2] = Nein) | H2: EN 81-80: im Bestandskatalog (organisatorisch) ASR A3.4 | I2: 4 von 4 offen
A3: Regel | B3: MF-Z01-R1 | C3: 100 | D3: [5.1 Beleuchtung an den Zuwegen zum Triebwerks-/Steuerungsraum vorhanden?] = Nein | E3: Hoch | F3: • Handlampe benutzen [O] | G3: • Geeignete Leuchten nachrüsten [T] | I3: offen | L3: =IF(J3<>"",J3,IF($J$2="Freigeben","Freigeben",""))
A4: Regel | B4: MF-Z01-R2 | C4: 100 | D4: [5.2 Beleuchtung an den Zuwegen ausreichend (mind. 50 Lux, funktionsfähig, Leuchten an geeigneter Stelle)?] = Nein | E4: Mittel | F4: • Handlampe benutzen [O] | G4: • Leuchten versetzen [T] | I4: offen | L4: =IF(J4<>"",J4,IF($J$2="Freigeben","Freigeben",""))
A5: Regel | B5: MF-Z01-R3 | C5: 100 | D5: [5.2a Defekte Leuchten oder Leuchtkörper an den Zuwegen?] = Ja | E5: Mittel | F5: • Defekte Leuchten umgehend instand setzen [T] | G5: • Beleuchtung der Zuwege dauerhaft instand halten (Prüfintervall festlegen) [O] | H5: Evidenz: abgeleitet | I5: offen | L5: =IF(J5<>"",J5,IF($J$2="Freigeben","Freigeben",""))
A6: Regel | B6: MF-Z01-R4 | C6: 1 | D6: [5.1 Beleuchtung an den Zuwegen zum Triebwerks-/Steuerungsraum vorhanden?] ist beantwortet | E6: Kein Risiko | F6: • Zustand erhalten; bei der wiederkehrenden Prüfung und der Betreiberkontrolle erneut prüfen [O] | H6: Auffangregel (Mechanik): greift, wenn keine Mangelregel zutrifft und alle Pflichtfragen beantwortet sind. | I6: offen (Auffang) | L6: =IF(J6<>"",J6,IF($J$2="Freigeben","Freigeben",""))
A7: Gefährdung | B7: MF-Z02 | D7: Unsicherer Verkehrsweg zum Triebwerks-/Steuerungsraum (Rutschen, Stolpern, Enge) Faktor: Mechanische Gefährdung durch Stolpern, Rutschen, Stürzen Betroffen: Beauftragte Person, Wartungspersonal Bewertungslogik: Höchste Stufe – alle zutreffenden Regeln zählen, maßgeblich ist die HÖCHSTE STUFE; Maßnahmen aller Treffer werden übernommen. Bewertet, wenn: immer Pflichtfragen: 5.3, 5.3a (wenn [5.3] = Nein), 5.3b (wenn [5.3] = Nein) | H7: EN 81-80: Nr. 19 (5.6.1) DIN EN 81-20 5.2.2.1 | I7: 4 von 4 offen
A8: Regel | B8: MF-Z02-R1 | C8: 100 | D8: [5.3 Sicherer, freier Verkehrsweg zum Triebwerks-/Steuerungsraum (trocken, sauber, ohne Stolperstellen)?] = Nein | E8: Mittel | F8: • Verkehrsweg vor dem Begehen prüfen, Stolper- und Rutschstellen kennzeichnen; rutschhemmendes Schuhwerk tragen [O] | G8: • Bodenbelag prüfen und häufig reinigen [O] | H8: [Prüfbericht 16.09.2026: konkrete Sofortmaßnahme statt „Vorsicht“] | I8: offen – geändert (Rev. 3) | L8: =IF(J8<>"",J8,IF($J$7="Freigeben","Freigeben",""))
A9: Regel | B9: MF-Z02-R3 | C9: 100 | D9: [5.3a Verkehrsweg rutschig, glatt oder verschmutzt?] = Ja | E9: Mittel | F9: • Rutschstellen kennzeichnen und reinigen lassen; rutschhemmendes Schuhwerk tragen [O] | G9: • Rutschhemmenden Bodenbelag herstellen bzw. Ursache der Verschmutzung/Nässe beseitigen [T] | H9: Prüfbericht 20.09.2026: Folgefrage mit eigener Maßnahme statt optionaler Frage ohne Wirkung. | I9: offen | L9: =IF(J9<>"",J9,IF($J$7="Freigeben","Freigeben",""))
A10: Regel | B10: MF-Z02-R4 | C10: 100 | D10: [5.3b Stolperstellen auf dem Verkehrsweg?] = Ja | E10: Mittel | F10: • Stolperstellen kennzeichnen (Warnmarkierung) und Beschäftigte hinweisen [O] | G10: • Stolperstellen beseitigen (Schwellen, Kabel, Bodenschäden) oder dauerhaft sichern [T] | H10: Prüfbericht 20.09.2026: Folgefrage mit eigener Maßnahme statt optionaler Frage ohne Wirkung. | I10: offen | L10: =IF(J10<>"",J10,IF($J$7="Freigeben","Freigeben",""))
A11: Regel | B11: MF-Z02-R2 | C11: 1 | D11: [5.3 Sicherer, freier Verkehrsweg zum Triebwerks-/Steuerungsraum (trocken, sauber, ohne Stolperstellen)?] ist beantwortet | E11: Kein Risiko | F11: • Zustand erhalten; bei der wiederkehrenden Prüfung und der Betreiberkontrolle erneut prüfen [O] | H11: Auffangregel (Mechanik): greift, wenn keine Mangelregel zutrifft und alle Pflichtfragen beantwortet sind. | I11: offen (Auffang) | L11: =IF(J11<>"",J11,IF($J$7="Freigeben","Freigeben",""))
A12: Gefährdung | B12: MF-Z03 | D12: Unsicherer Aufstieg (Treppe, Leiter) zum Triebwerksraum Faktor: Mechanische Gefährdung durch Absturz Betroffen: Beauftragte Person, Wartungspersonal Bewertungslogik: Höchste Stufe – alle zutreffenden Regeln zählen, maßgeblich ist die HÖCHSTE STUFE; Maßnahmen aller Treffer werden übernommen. Bewertet, wenn: [4.7 Eigener Triebwerks-/Maschinenraum vorhanden?] = Ja Pflichtfragen: 5.5, 5.6 (wenn [5.5] ≠ „Ebenerdig / kein Aufstieg nötig") | H12: EN 81-80: Nr. 19 (5.6.1) DIN EN 81-20 5.2.2.2 ASR A1.8 | I12: 6 von 6 offen
A13: Regel | B13: MF-Z03-R1 | C13: 100 | D13: [5.5 Art des Aufstiegs zum Triebwerksraum] = „Treppe ohne Handlauf" | E13: Mittel | F13: • Aufstieg nur mit freien Händen (Dreipunktkontakt); Werkzeug und Material getrennt hochreichen; Betreiber zur Instandsetzung auffordern [O] | G13: • Handlauf nachrüsten [T] | H13: [Prüfbericht 16.09.2026: konkrete Sofortmaßnahme statt „Vorsicht“] | I13: offen – geändert (Rev. 3) | L13: =IF(J13<>"",J13,IF($J$12="Freigeben","Freigeben",""))
A14: Regel | B14: MF-Z03-R2 | C14: 100 | D14: [5.5 Art des Aufstiegs zum Triebwerksraum] = „Zug-/Klapptreppe nicht sicherheitsgerecht" | E14: Mittel | F14: • Aufstieg nur mit freien Händen (Dreipunktkontakt); Werkzeug und Material getrennt hochreichen; Betreiber zur Instandsetzung auffordern [O] | G14: • Treppe erneuern [T] | H14: [Prüfbericht 16.09.2026: konkrete Sofortmaßnahme statt „Vorsicht“] | I14: offen – geändert (Rev. 3) | L14: =IF(J14<>"",J14,IF($J$12="Freigeben","Freigeben",""))
A15: Regel | B15: MF-Z03-R3 | C15: 100 | D15: [5.5 Art des Aufstiegs zum Triebwerksraum] = „Nur mobile Leiter / Anlegeleiter" | E15: Hoch | F15: • Leiter gegen Wegrutschen sichern, nur zu zweit benutzen [O] | G15: • Fest angebrachte Steigleiter mit Haltegriffen oder Treppe herstellen [T] | H15: Entschieden 2026-09-02: K-Z04. [Freigabe bezog sich auf einen früheren Stand (Regel, abhängige Fragen oder Gefährdungslogik geändert) – neu prüfen] Evidenz: abgeleitet | I15: offen – geändert (Rev. 2) | L15: =IF(J15<>"",J15,IF($J$12="Freigeben","Freigeben",""))
A16: Regel | B16: MF-Z03-R4 | C16: 100 | D16: [5.5 Art des Aufstiegs zum Triebwerksraum] = „Kein sicherer Aufstieg vorhanden" | E16: Hoch | F16: • Geeignete Aufstiegshilfe verwenden [O] | G16: • Sichere Treppe / Leiter / Zugang schaffen [T] | I16: offen | L16: =IF(J16<>"",J16,IF($J$12="Freigeben","Freigeben",""))
A17: Regel | B17: MF-Z03-R5 | C17: 100 | D17: [5.6 Bruch- oder Kippgefahr am Aufstieg (beschädigte Stufen, lose Leiter, fehlende Befestigung)?] = Ja | E17: Hoch | F17: • Nur mit Absturzsicherung begehen [O] | G17: • Treppe / Leiter erneuern [T] | I17: offen | L17: =IF(J17<>"",J17,IF($J$12="Freigeben","Freigeben",""))
A18: Regel | B18: MF-Z03-R6 | C18: 1 | D18: [5.5 Art des Aufstiegs zum Triebwerksraum] ist beantwortet | E18: Kein Risiko | F18: • Zustand erhalten; bei der wiederkehrenden Prüfung und der Betreiberkontrolle erneut prüfen [O] | H18: Auffangregel (Mechanik): greift, wenn keine Mangelregel zutrifft und alle Pflichtfragen beantwortet sind. | I18: offen (Auffang) | L18: =IF(J18<>"",J18,IF($J$12="Freigeben","Freigeben",""))
A19: Gefährdung | B19: MF-Z04 | D19: Absturzgefahr im Zugangsbereich (Dachfläche, Absturzkante, Übersteigen) Faktor: Mechanische Gefährdung durch Absturz Betroffen: Beauftragte Person, Wartungspersonal Bewertungslogik: Höchste Stufe – alle zutreffenden Regeln zählen, maßgeblich ist die HÖCHSTE STUFE; Maßnahmen aller Treffer werden übernommen. Bewertet, wenn: immer Pflichtfragen: 5.7, 5.7a (wenn [5.7] = Ja), 5.7b (wenn ([5.7] = Ja UND [5.7a] = Nein)), 5.8 | H19: EN 81-80: im Bestandskatalog (organisatorisch) ASR A2.1 | I19: 4 von 4 offen
A20: Regel | B20: MF-Z04-R1 | C20: 100 | D20: [5.7 Führt der Zugang über eine Dachfläche, Dachkante, Empore oder eine andere Absturzkante?] = Ja UND [5.7a Absturzkante durch Geländer oder Umwehrung dauerhaft gesichert?] = Nein UND [5.7b Verkehrsweg an der Absturzkante festgelegt und gekennzeichnet?] = Nein | E20: Hoch | F20: • PSA gegen Absturz mit festgelegtem Anschlagpunkt verwenden, sonst Zugangsverbot [O] | G20: • Absturzsicherung und Anschlagpunkte herstellen, Verkehrswege festlegen [T] | I20: offen | L20: =IF(J20<>"",J20,IF($J$19="Freigeben","Freigeben",""))
A21: Regel | B21: MF-Z04-R2 | C21: 100 | D21: [5.7 Führt der Zugang über eine Dachfläche, Dachkante, Empore oder eine andere Absturzkante?] = Ja UND [5.7a Absturzkante durch Geländer oder Umwehrung dauerhaft gesichert?] = Nein UND [5.7b Verkehrsweg an der Absturzkante festgelegt und gekennzeichnet?] = Ja | E21: Mittel | F21: • Nur den festgelegten, gekennzeichneten Verkehrsweg nutzen; mindestens 2 m Abstand zur Absturzkante halten [O] | G21: • Geländer oder dauerhafte Absturzsicherung anbringen [T] | H21: [Prüfbericht 16.09.2026: konkrete Sofortmaßnahme statt „Vorsicht“] | I21: offen – geändert (Rev. 2) | L21: =IF(J21<>"",J21,IF($J$19="Freigeben","Freigeben",""))
A22: Regel | B22: MF-Z04-R3 | C22: 100 | D22: [5.8 Muss ein Treppenauge, eine Brüstung oder ein Fenster überstiegen werden?] = Ja | E22: Hoch | F22: • Zugang sperren und alternative Zugangsmöglichkeit festlegen [O] | G22: • Zugang baulich ändern [T] | I22: offen | L22: =IF(J22<>"",J22,IF($J$19="Freigeben","Freigeben",""))
A23: Regel | B23: MF-Z04-R4 | C23: 1 | D23: [5.7 Führt der Zugang über eine Dachfläche, Dachkante, Empore oder eine andere Absturzkante?] ist beantwortet | E23: Kein Risiko | F23: • Zustand erhalten; bei der wiederkehrenden Prüfung und der Betreiberkontrolle erneut prüfen [O] | H23: Auffangregel (Mechanik): greift, wenn keine Mangelregel zutrifft und alle Pflichtfragen beantwortet sind. | I23: offen (Auffang) | L23: =IF(J23<>"",J23,IF($J$19="Freigeben","Freigeben",""))
A24: Gefährdung | B24: MF-Z05 | D24: Einschließen im Zugangsbereich / Triebwerksraum (keine Panikfunktion) Faktor: Sonstige Gefährdung durch Einschließen von Personen Betroffen: Beauftragte Person, Wartungspersonal Bewertungslogik: Vorrang – es gilt die zutreffende Regel mit der HÖCHSTEN PRIORITÄT (so wirken Kompensationen); bei gleicher Priorität die höhere Stufe. Bewertet, wenn: [4.7 Eigener Triebwerks-/Maschinenraum vorhanden?] = Ja Pflichtfragen: 5.9 | H24: EN 81-80: im Bestandskatalog (organisatorisch) DIN EN 81-20 5.2.3.3 | I24: 3 von 3 offen
A25: Regel | B25: MF-Z05-R1 | C25: 100 | D25: [5.9 Lässt sich der Zugangsbereich / Triebwerksraum jederzeit von innen verlassen?] = „Nein – Einschließen möglich" | E25: Hoch | F25: • Nur zu zweit betreten, an- und abmelden, Tür gegen Zufallen sichern [O] | G25: • Panikschloss installieren oder zweiten Fluchtweg schaffen [T] | I25: offen | L25: =IF(J25<>"",J25,IF($J$24="Freigeben","Freigeben",""))
A26: Regel | B26: MF-Z05-R2 | C26: 100 | D26: [5.9 Lässt sich der Zugangsbereich / Triebwerksraum jederzeit von innen verlassen?] = „Nur mit Schlüssel, Schlüssel dauerhaft innen hinterlegt" | E26: Mittel | F26: • Vor dem Betreten Schlüssel prüfen, beim Betreiber an- und abmelden [O] | G26: • Panikschloss nachrüsten [T] | I26: offen | L26: =IF(J26<>"",J26,IF($J$24="Freigeben","Freigeben",""))
A27: Regel | B27: MF-Z05-R3 | C27: 1 | D27: [5.9 Lässt sich der Zugangsbereich / Triebwerksraum jederzeit von innen verlassen?] ist beantwortet | E27: Kein Risiko | F27: • Zustand erhalten; bei der wiederkehrenden Prüfung und der Betreiberkontrolle erneut prüfen [O] | H27: Auffangregel (Mechanik): greift, wenn keine Mangelregel zutrifft und alle Pflichtfragen beantwortet sind. | I27: offen (Auffang) | L27: =IF(J27<>"",J27,IF($J$24="Freigeben","Freigeben",""))
A28: Gefährdung | B28: MF-Z06 | D28: Zugang über fremde Räume, erschwerter Material- und Werkzeugtransport Faktor: Physische Belastung / ergonomische Gefährdung Betroffen: Beauftragte Person, Wartungspersonal Bewertungslogik: Höchste Stufe – alle zutreffenden Regeln zählen, maßgeblich ist die HÖCHSTE STUFE; Maßnahmen aller Treffer werden übernommen. Bewertet, wenn: immer Pflichtfragen: 5.10, 5.11 | H28: EN 81-80: im Bestandskatalog (organisatorisch) DIN EN 81-20 5.2.2.1 | I28: 4 von 4 offen
A29: Regel | B29: MF-Z06-R1 | C29: 100 | D29: [5.10 Führt der Zugang durch fremde Räume?] = „Durch eine Wohnung oder einen nur zeitweise zugänglichen Bereich" | E29: Hoch | F29: • Zutritt vorab vereinbaren, im Notfall Dritte hinzuziehen [O] | G29: • Zugang dauerhaft ändern [T] | I29: offen | L29: =IF(J29<>"",J29,IF($J$28="Freigeben","Freigeben",""))
A30: Regel | B30: MF-Z06-R2 | C30: 100 | D30: [5.10 Führt der Zugang durch fremde Räume?] = „Durch Arbeits-, Lager- oder Technikräume Dritter" | E30: Mittel | F30: • Zutritt vorab mit dem Betreiber abstimmen (Schlüssel, Begleitung); Material in tragbaren Teilmengen transportieren [O] | G30: • Eigenständigen Zugang schaffen oder Wegeführung verbindlich festlegen [T] | H30: [Prüfbericht 16.09.2026: konkrete Sofortmaßnahme statt „Vorsicht“] | I30: offen – geändert (Rev. 2) | L30: =IF(J30<>"",J30,IF($J$28="Freigeben","Freigeben",""))
A31: Regel | B31: MF-Z06-R3 | C31: 100 | D31: [5.11 Erschwert die Art des Zugangs den Transport von Material und Werkzeug (z. B. nur über Leiter, Dachluke, enge Wendeltreppe)?] = Ja | E31: Mittel | F31: • Geeignete Transporthilfen verwenden [O] | G31: • Zugang so herrichten, dass Material sicher transportiert werden kann [T] | I31: offen | L31: =IF(J31<>"",J31,IF($J$28="Freigeben","Freigeben",""))
A32: Regel | B32: MF-Z06-R4 | C32: 1 | D32: [5.10 Führt der Zugang durch fremde Räume?] ist beantwortet | E32: Kein Risiko | F32: • Zustand erhalten; bei der wiederkehrenden Prüfung und der Betreiberkontrolle erneut prüfen [O] | H32: Auffangregel (Mechanik): greift, wenn keine Mangelregel zutrifft und alle Pflichtfragen beantwortet sind. | I32: offen (Auffang) | L32: =IF(J32<>"",J32,IF($J$28="Freigeben","Freigeben",""))
A33: Gefährdung | B33: MF-Z07 | D33: Fehlende oder unzureichende Zugangstür zum Triebwerks-/Maschinenraum bzw. nicht abschließbarer Steuerschrank Faktor: Sonstige Gefährdung durch Einschließen von Personen Betroffen: Beauftragte Person, Wartungspersonal, Nutzer Bewertungslogik: Höchste Stufe – alle zutreffenden Regeln zählen, maßgeblich ist die HÖCHSTE STUFE; Maßnahmen aller Treffer werden übernommen. Bewertet, wenn: immer Pflichtfragen: 4.7, 5.12 (wenn [4.7] = Ja), 5.14 (wenn [4.7] = Nein), 5.12a (wenn [5.12] = Ja), 5.12b (wenn [5.12] = Ja), 5.12c (wenn [5.12] = Ja) | H33: EN 81-80: Nr. 19 (5.6.1) DIN EN 81-20 5.2.3.3 DIN EN 81-20 5.2.6 | I33: 6 von 6 offen
A34: Regel | B34: MF-Z07-R1 | C34: 100 | D34: [5.12 Zugangstür zum Triebwerks-/Maschinenraum vorhanden?] = Nein | E34: Hoch | F34: • Zugang gegen unbefugten Zutritt sichern [O] | G34: • Abschließbare Zugangstür nach DIN EN 81-20, 5.2.3.3 herstellen [T] | I34: offen | L34: =IF(J34<>"",J34,IF($J$33="Freigeben","Freigeben",""))
A35: Regel | B35: MF-Z07-R2 | C35: 100 | D35: [5.12a Zugangstür abschließbar (Zutritt nur für befugte Personen)?] = Nein | E35: Hoch | F35: • Zugang gegen unbefugten Zutritt sichern [O] | G35: • Abschließbare Zugangstür nach DIN EN 81-20, 5.2.3.3 herstellen [T] | I35: offen | L35: =IF(J35<>"",J35,IF($J$33="Freigeben","Freigeben",""))
A36: Regel | B36: MF-Z07-R3 | C36: 100 | D36: [5.12b Zugangstür unbeschädigt und leichtgängig?] = Nein | E36: Mittel | F36: • Tür gangbar machen [T] | G36: • Tür instand setzen oder ersetzen [T] | I36: offen | L36: =IF(J36<>"",J36,IF($J$33="Freigeben","Freigeben",""))
A37: Regel | B37: MF-Z07-R4 | C37: 100 | D37: [5.12c Durchgangsmaß der Zugangstür ausreichend (mind. 2,00 m hoch, 0,60 m breit)?] = Nein | E37: Mittel | F37: • Anstoßstelle kennzeichnen, Kopfschutz verwenden [O] | G37: • Türöffnung nach DIN EN 81-20, 5.2.3 anpassen [T] | I37: offen | L37: =IF(J37<>"",J37,IF($J$33="Freigeben","Freigeben",""))
A38: Regel | B38: MF-Z07-R6 | C38: 100 | D38: [5.14 Ohne Triebwerksraum: Steuerschrank (an der Haltestelle oder im Schacht) abschließbar, Zutritt nur für befugte Personen?] = Nein | E38: Hoch | F38: • Steuerschrank gegen unbefugten Zugriff sichern (Schloss, Zutritt beschränken); Betreiber informieren [O] | G38: • Abschließbaren Steuerschrank herstellen, Zutritt nur für befugte Personen (DIN EN 81-20 5.2.6, Steuerschränke außerhalb von Triebwerksräumen) [T] | H38: Prüfbericht 20.09.2026: Gegenstück zu 5.12a für maschinenraumlose Anlagen – bisher entfiel die Gefährdung dort vollständig (nur im Cyber-Teil 2.1 erfasst). Evidenz: abgeleitet | I38: offen | L38: =IF(J38<>"",J38,IF($J$33="Freigeben","Freigeben",""))
A39: Regel | B39: MF-Z07-R7 | C39: 1 | D39: [4.7 Eigener Triebwerks-/Maschinenraum vorhanden?] ist beantwortet | E39: Kein Risiko | F39: • Zustand erhalten; bei der wiederkehrenden Prüfung und der Betreiberkontrolle erneut prüfen [O] | H39: Auffangregel (Mechanik): greift, wenn keine Mangelregel zutrifft und alle Pflichtfragen beantwortet sind. | I39: offen (Auffang) | L39: =IF(J39<>"",J39,IF($J$33="Freigeben","Freigeben",""))
A40: Gefährdung | B40: MF-Z08 | D40: Fehlende oder versperrte Flucht- und Rettungswege im Bereich des Triebwerks-/Steuerungsraums Faktor: Gefährdung durch fehlende oder versperrte Flucht- und Rettungswege Betroffen: Beauftragte Person, Wartungspersonal Bewertungslogik: Höchste Stufe – alle zutreffenden Regeln zählen, maßgeblich ist die HÖCHSTE STUFE; Maßnahmen aller Treffer werden übernommen. Bewertet, wenn: immer Pflichtfragen: 5.13, 5.13a (wenn [5.13] = Ja), 5.13b (wenn [5.13] = Ja) | H40: EN 81-80: im Bestandskatalog (organisatorisch) ASR A2.3 ArbStättV § 4 | I40: 1 von 4 offen
...

Sheet M Triebwerksraum
A1: Art | B1: Code | C1: Prio | D1: Gefährdung / Bedingung | E1: Stufe | F1: Sofortmaßnahme | G1: Mittelfristige Maßnahme | H1: Hinweis / Quelle | I1: Status | J1: Entscheidung | K1: Korrektur | L1: wirksam
A2: Gefährdung | B2: MF-M01 | D2: Unzureichende Beleuchtung im Triebwerks-/Maschinenraum Faktor: Gefährdung durch Arbeitsumgebungsbedingungen (unzureichende Beleuchtung) Betroffen: Beauftragte Person, Wartungspersonal Bewertungslogik: Höchste Stufe – alle zutreffenden Regeln zählen, maßgeblich ist die HÖCHSTE STUFE; Maßnahmen aller Treffer werden übernommen. Bewertet, wenn: [4.7 Eigener Triebwerks-/Maschinenraum vorhanden?] = Ja Pflichtfragen: 5.20, 5.21 (wenn [5.20] = Ja), 5.22 (wenn [5.20] = Ja), 5.23 (wenn [5.20] = Ja) | H2: EN 81-80: Nr. 23 (5.6.5) DIN EN 81-20 5.2.1.4.2 | I2: 5 von 5 offen
A3: Regel | B3: MF-M01-R1 | C3: 100 | D3: [5.20 Beleuchtung im Triebwerks-/Maschinenraum vorhanden?] = Nein | E3: Hoch | F3: • Handlampe benutzen [O] | G3: • Geeignete Leuchten nachrüsten [T] | I3: offen | L3: =IF(J3<>"",J3,IF($J$2="Freigeben","Freigeben",""))
A4: Regel | B4: MF-M01-R2 | C4: 100 | D4: [5.21 Beleuchtungsstärke an den Arbeitsflächen (Antrieb, Steuerschrank) mind. 200 Lux, Leuchten funktionsfähig?] = Nein | E4: Mittel | F4: • Handlampe benutzen [O] | G4: • Geeignete Leuchten nachrüsten [T] | I4: offen | L4: =IF(J4<>"",J4,IF($J$2="Freigeben","Freigeben",""))
A5: Regel | B5: MF-M01-R3 | C5: 100 | D5: [5.22 Leuchten an geeigneter Stelle (Arbeitsflächen nicht abgeschattet)?] = Nein | E5: Mittel | F5: • Handlampe benutzen [O] | G5: • Leuchten versetzen [T] | I5: offen | L5: =IF(J5<>"",J5,IF($J$2="Freigeben","Freigeben",""))
A6: Regel | B6: MF-M01-R4 | C6: 100 | D6: [5.23 Leuchten im Kopfbereich mit Splitterschutz / bruchsicher?] = Nein | E6: Mittel | F6: • Beschädigte Leuchten sofort ersetzen [T] | G6: • Splitterschutz nachrüsten [T] | H6: [Prüfbericht: H11 – Sofortmaßnahme ergänzt] | I6: offen – geändert (Rev. 2) | L6: =IF(J6<>"",J6,IF($J$2="Freigeben","Freigeben",""))
A7: Regel | B7: MF-M01-R5 | C7: 1 | D7: [5.20 Beleuchtung im Triebwerks-/Maschinenraum vorhanden?] ist beantwortet | E7: Kein Risiko | F7: • Zustand erhalten; bei der wiederkehrenden Prüfung und der Betreiberkontrolle erneut prüfen [O] | H7: Auffangregel (Mechanik): greift, wenn keine Mangelregel zutrifft und alle Pflichtfragen beantwortet sind. | I7: offen (Auffang) | L7: =IF(J7<>"",J7,IF($J$2="Freigeben","Freigeben",""))
A8: Gefährdung | B8: MF-M02 | D8: Unzureichender Schutz gegen elektrischen Schlag (offene Schalttafel, offene Kontakte, fehlende Berührungssicherheit) Faktor: Elektrische Gefährdung durch Berühren spannungsführender Teile Betroffen: Beauftragte Person, Wartungspersonal Bewertungslogik: Höchste Stufe – alle zutreffenden Regeln zählen, maßgeblich ist die HÖCHSTE STUFE; Maßnahmen aller Treffer werden übernommen. Bewertet, wenn: immer Pflichtfragen: 5.30, 5.31 (wenn [5.30] = Nein), 5.32 (wenn [5.30] = Nein), 5.33 (wenn [5.30] = Nein), 5.34 (wenn [5.30] = Nein), 5.35 | H8: EN 81-80: Nr. 66 (5.13.1) DIN EN 81-20 5.10.1.2 DGUV Vorschrift 3 TRBS 3121 Anh. 1 Nr. 21 (Schutz gegen elektrischen Schlag und Kennzeichnung) | I8: 7 von 7 offen
A9: Regel | B9: MF-M02-R1 | C9: 100 | D9: [5.31 Offene Schalttafel ohne Schaltschrank vorhanden?] = Ja | E9: Hoch | F9: • Bei Betreten des Maschinenraumes ausschalten [O] | G9: • Steuerung erneuern [T] | I9: offen | L9: =IF(J9<>"",J9,IF($J$8="Freigeben","Freigeben",""))
A10: Regel | B10: MF-M02-R2 | C10: 100 | D10: [5.32 Offene Kontakte oder Schalter an Maschine, Kopierwerk oder Begrenzer?] = Ja | E10: Hoch | F10: • Bei Betreten des Maschinenraumes ausschalten [O] | G10: • Maschine erneuern oder Bauteile abdecken oder ersetzen [T] | I10: offen | L10: =IF(J10<>"",J10,IF($J$8="Freigeben","Freigeben",""))
A11: Regel | B11: MF-M02-R3 | C11: 100 | D11: [5.33 Nicht berührungssichere Bauteile im Schaltschrank (bei geöffneter Tür erreichbar)?] = Ja | E11: Mittel | F11: • Bei Arbeiten am Schaltschrank immer ausschalten [O] | G11: • Berührungssichere Bauteile nachrüsten [T] | I11: offen | L11: =IF(J11<>"",J11,IF($J$8="Freigeben","Freigeben",""))
A12: Regel | B12: MF-M02-R4 | C12: 100 | D12: [5.30 Alle spannungsführenden Teile berührungssicher (Abdeckungen vorhanden, Schaltschrank geschlossen)?] = Nein | E12: Mittel | F12: • Bei Arbeiten immer ausschalten [O] | G12: • Berührungssichere Bauteile nachrüsten [T] | I12: offen | L12: =IF(J12<>"",J12,IF($J$8="Freigeben","Freigeben",""))
A13: Regel | B13: MF-M02-R5 | C13: 100 | D13: [5.35 Nachweis der elektrischen Prüfung der AUFZUGSANLAGE nach DGUV Vorschrift 3 vorhanden (Steuerung, Antrieb, Leitungen der Anlage; Prüfplakette / Protokoll aktuell)?] = Nein | E13: Mittel | F13: • Arbeiten an der Elektrik nur durch Fachkundige, ggf. Zusatzschutz (PRCD-S) [O] | G13: • Bei Notwendigkeit DGUV V3 Prüfung beauftragen, Plakette erneuern [T] | H13: Entschieden 2026-09-02: K-M01. [Freigabe bezog sich auf einen früheren Stand (Regel, abhängige Fragen oder Gefährdungslogik geändert) – neu prüfen] | I13: offen – geändert (Rev. 3) | L13: =IF(J13<>"",J13,IF($J$8="Freigeben","Freigeben",""))
A14: Regel | B14: MF-M02-R7 | C14: 100 | D14: [5.34 Warnkennzeichnung für offene elektrische Kontakte vorhanden?] = Nein | E14: Niedrig | F14: • Offene Kontakte provisorisch mit Warnzeichen W012 kennzeichnen [O] | G14: • Dauerhafte Warnkennzeichnung anbringen; sie ersetzt den Berührungsschutz nicht [O] | H14: Prüfbericht 20.09.2026: bisher optionale Frage ohne Regelwirkung. Eigener geringer Mangel, ausdrücklich KEINE Kompensation (Entscheidung K-K10). Evidenz: abgeleitet | I14: offen | L14: =IF(J14<>"",J14,IF($J$8="Freigeben","Freigeben",""))
A15: Regel | B15: MF-M02-R6 | C15: 1 | D15: [5.30 Alle spannungsführenden Teile berührungssicher (Abdeckungen vorhanden, Schaltschrank geschlossen)?] ist beantwortet | E15: Kein Risiko | F15: • Zustand erhalten; bei der wiederkehrenden Prüfung und der Betreiberkontrolle erneut prüfen [O] | H15: Auffangregel (Mechanik): greift, wenn keine Mangelregel zutrifft und alle Pflichtfragen beantwortet sind. | I15: offen (Auffang) | L15: =IF(J15<>"",J15,IF($J$8="Freigeben","Freigeben",""))
A16: Gefährdung | B16: MF-M03 | D16: Fehlender oder unzureichender Schutz an drehenden Teilen (Treibscheibe, Umlenkrollen, Begrenzer) Faktor: Mechanische Gefährdung durch rotierende Teile (Erfassen, Einziehen) Betroffen: Wartungspersonal Bewertungslogik: Höchste Stufe – alle zutreffenden Regeln zählen, maßgeblich ist die HÖCHSTE STUFE; Maßnahmen aller Treffer werden übernommen. Bewertet, wenn: [3.1 Aufzugsart] ist eines von „Seil-/Riemenaufzug (Treibscheibe)" / „Trommel- oder Kettenaufzug" / „Seil-Hydraulikaufzug (indirekt)" Pflichtfragen: 5.40, 5.41, 5.42 | H16: EN 81-80: Nr. 47 (5.9.1), Nr. 48 (5.9.1), Nr. 49 (5.9.1) DIN EN 81-20 5.9.3.1 | I16: 5 von 5 offen
A17: Regel | B17: MF-M03-R1 | C17: 100 | D17: [5.42 Abdeckung der Einzugstellen insgesamt] = „Einzugstellen offen" | E17: Hoch | F17: • Bei Betreten des Maschinenraumes ausschalten [O] | G17: • Komplettabdeckungen nachrüsten [T] | I17: offen | L17: =IF(J17<>"",J17,IF($J$16="Freigeben","Freigeben",""))
A18: Regel | B18: MF-M03-R2 | C18: 100 | D18: [5.40 Einzugsschutz an Treibscheibe, Umlenkrollen und Kopierwerk vorhanden?] = Nein | E18: Hoch | F18: • Bei Betreten des Maschinenraumes ausschalten [O] | G18: • Komplettabdeckungen nachrüsten [T] | I18: offen | L18: =IF(J18<>"",J18,IF($J$16="Freigeben","Freigeben",""))
A19: Regel | B19: MF-M03-R3 | C19: 100 | D19: [5.42 Abdeckung der Einzugstellen insgesamt] = „Teilweise abgedeckt" | E19: Mittel | F19: • Bei Betreten des Maschinenraumes ausschalten [O] | G19: • Komplettabdeckungen nachrüsten [T] | I19: offen | L19: =IF(J19<>"",J19,IF($J$16="Freigeben","Freigeben",""))
A20: Regel | B20: MF-M03-R4 | C20: 100 | D20: [5.40 Einzugsschutz an Treibscheibe, Umlenkrollen und Kopierwerk vorhanden?] = Ja UND [5.41 Einzugsschutz am Geschwindigkeitsbegrenzer vorhanden?] = Nein | E20: Mittel | F20: • Bei Arbeiten am Geschwindigkeitsbegrenzer ausschalten [O] | G20: • Abdeckungen nachrüsten [T] | I20: offen | L20: =IF(J20<>"",J20,IF($J$16="Freigeben","Freigeben",""))
A21: Regel | B21: MF-M03-R5 | C21: 1 | D21: [5.40 Einzugsschutz an Treibscheibe, Umlenkrollen und Kopierwerk vorhanden?] ist beantwortet | E21: Kein Risiko | F21: • Zustand erhalten; bei der wiederkehrenden Prüfung und der Betreiberkontrolle erneut prüfen [O] | H21: Auffangregel (Mechanik): greift, wenn keine Mangelregel zutrifft und alle Pflichtfragen beantwortet sind. | I21: offen (Auffang) | L21: =IF(J21<>"",J21,IF($J$16="Freigeben","Freigeben",""))
A22: Gefährdung | B22: MF-M04 | D22: Unzureichende Raumhöhe, Bewegungs- und Freiflächen im Triebwerksraum Faktor: Physische Belastung / ergonomische Gefährdung Betroffen: Beauftragte Person, Wartungspersonal Bewertungslogik: Höchste Stufe – alle zutreffenden Regeln zählen, maßgeblich ist die HÖCHSTE STUFE; Maßnahmen aller Treffer werden übernommen. Bewertet, wenn: [4.7 Eigener Triebwerks-/Maschinenraum vorhanden?] = Ja Pflichtfragen: 5.43, 5.44, 5.45 | H22: EN 81-80: Nr. 21 (5.6.3) DIN EN 81-20 5.2.6.3.2 | I22: 4 von 4 offen
A23: Regel | B23: MF-M04-R1 | C23: 100 | D23: [5.44 Freifläche für Notbetrieb/Handrad mind. 0,50 m × 0,60 m vor dem Antrieb vorhanden?] = Nein | E23: Hoch | F23: • Fläche sofort freiräumen [O] | G23: • Freifläche dauerhaft sicherstellen und kennzeichnen [O] | I23: offen | L23: =IF(J23<>"",J23,IF($J$22="Freigeben","Freigeben",""))
A24: Regel | B24: MF-M04-R2 | C24: 100 | D24: [5.43 Lichte Höhe im Gehbereich mind. 1,80 m?] = Nein | E24: Mittel | F24: • Niedrige Stellen kennzeichnen (Warnmarkierung, Polsterung), Beschäftigte unterweisen [O] | G24: • Lichte Höhe von 1,80 m im Gehbereich herstellen (Umbau, Verlegung von Einbauten) [T] | I24: offen | L24: =IF(J24<>"",J24,IF($J$22="Freigeben","Freigeben",""))
A25: Regel | B25: MF-M04-R3 | C25: 100 | D25: [5.45 Bewegungsflächen durch Lagerung eingeengt?] = Ja | E25: Mittel | F25: • Flächen sofort freiräumen [O] | G25: • Lagerung im Triebwerksraum dauerhaft unterbinden [O] | I25: offen | L25: =IF(J25<>"",J25,IF($J$22="Freigeben","Freigeben",""))
A26: Regel | B26: MF-M04-R4 | C26: 1 | D26: [5.43 Lichte Höhe im Gehbereich mind. 1,80 m?] ist beantwortet | E26: Kein Risiko | F26: • Zustand erhalten; bei der wiederkehrenden Prüfung und der Betreiberkontrolle erneut prüfen [O] | H26: Auffangregel (Mechanik): greift, wenn keine Mangelregel zutrifft und alle Pflichtfragen beantwortet sind. | I26: offen (Auffang) | L26: =IF(J26<>"",J26,IF($J$22="Freigeben","Freigeben",""))
A27: Gefährdung | B27: MF-M05 | D27: Unterschiedliche Ebenen, Podeste und Bodenöffnungen im Triebwerksraum ungesichert Faktor: Mechanische Gefährdung durch Absturz Betroffen: Beauftragte Person, Wartungspersonal Bewertungslogik: Höchste Stufe – alle zutreffenden Regeln zählen, maßgeblich ist die HÖCHSTE STUFE; Maßnahmen aller Treffer werden übernommen. Bewertet, wenn: [4.7 Eigener Triebwerks-/Maschinenraum vorhanden?] = Ja Pflichtfragen: 5.46, 5.46a (wenn [5.46] = Ja), 5.46b (wenn [5.46] = Ja), 5.47 | H27: EN 81-80: Nr. 22 (5.6.4) DIN EN 81-20 5.2.6.3.2.4 | I27: 4 von 4 offen
A28: Regel | B28: MF-M05-R1 | C28: 100 | D28: [5.46 Niveauunterschiede über 0,50 m im Raum vorhanden?] = Ja UND [5.46a Niveauunterschied durch Treppe oder Leiter überwindbar?] = Nein | E28: Mittel | F28: • Sichere Aufstiegshilfe verwenden [O] | G28: • Treppe oder Leiter nach DIN EN 81-20, 5.2.6.3.2.4 herstellen [T] | I28: offen | L28: =IF(J28<>"",J28,IF($J$27="Freigeben","Freigeben",""))
A29: Regel | B29: MF-M05-R2 | C29: 100 | D29: [5.46b Podest mit Absturzhöhe über 1,00 m ohne Geländer?] = Ja | E29: Hoch | F29: • Bereich absperren, PSA gegen Absturz verwenden [O] | G29: • Geländer nachrüsten [T] | I29: offen | L29: =IF(J29<>"",J29,IF($J$27="Freigeben","Freigeben",""))
A30: Regel | B30: MF-M05-R3 | C30: 100 | D30: [5.47 Ungesicherte Bodenöffnung oder Vertiefung im Raum?] = Ja | E30: Hoch | F30: • Öffnung abdecken oder absperren [O] | G30: • Dauerhafte Abdeckung und umlaufendes Geländer anbringen [T] | I30: offen | L30: =IF(J30<>"",J30,IF($J$27="Freigeben","Freigeben",""))
A31: Regel | B31: MF-M05-R4 | C31: 1 | D31: [5.46 Niveauunterschiede über 0,50 m im Raum vorhanden?] ist beantwortet | E31: Kein Risiko | F31: • Zustand erhalten; bei der wiederkehrenden Prüfung und der Betreiberkontrolle erneut prüfen [O] | H31: Auffangregel (Mechanik): greift, wenn keine Mangelregel zutrifft und alle Pflichtfragen beantwortet sind. | I31: offen (Auffang) | L31: =IF(J31<>"",J31,IF($J$27="Freigeben","Freigeben",""))
A32: Gefährdung | B32: MF-M06 | D32: Rutschiger, verschmutzter oder ölverunreinigter Boden im Triebwerksraum Faktor: Mechanische Gefährdung durch Stolpern, Rutschen, Stürzen Betroffen: Beauftragte Person, Wartungspersonal Bewertungslogik: Höchste Stufe – alle zutreffenden Regeln zählen, maßgeblich ist die HÖCHSTE STUFE; Maßnahmen aller Treffer werden übernommen. Bewertet, wenn: [4.7 Eigener Triebwerks-/Maschinenraum vorhanden?] = Ja Pflichtfragen: 5.48, 5.49, 5.50 | H32: EN 81-80: Nr. 20 (5.6.2) DIN EN 81-20 5.2.1.9 | I32: 4 von 4 offen
A33: Regel | B33: MF-M06-R1 | C33: 100 | D33: [5.50 Ausgetretenes Öl / Hydrauliköl ohne Auffangmöglichkeit?] = Ja | E33: Hoch | F33: • Öl aufnehmen, Leckage abstellen, Bereich sichern [O] | G33: • Auffangwanne herstellen und Leckage dauerhaft beseitigen (Wasserhaushaltsgesetz beachten) [T] | I33: offen | L33: =IF(J33<>"",J33,IF($J$32="Freigeben","Freigeben",""))
A34: Regel | B34: MF-M06-R2 | C34: 100 | D34: [5.48 Boden rutschhemmend und sauber?] = Nein | E34: Mittel | F34: • Reinigen, abstumpfendes Material einsetzen [O] | G34: • Reinigung in den Wartungsplan aufnehmen [O] | I34: offen | L34: =IF(J34<>"",J34,IF($J$32="Freigeben","Freigeben",""))
A35: Regel | B35: MF-M06-R3 | C35: 100 | D35: [5.49 Boden ölfest gestrichen und unbeschädigt?] = Nein | E35: Mittel | F35: • Ölbindemittel bereitstellen und Verunreinigungen aufnehmen [O] | G35: • Ölfesten Anstrich erneuern [T] | I35: offen | L35: =IF(J35<>"",J35,IF($J$32="Freigeben","Freigeben",""))
A36: Regel | B36: MF-M06-R4 | C36: 1 | D36: [5.48 Boden rutschhemmend und sauber?] ist beantwortet | E36: Kein Risiko | F36: • Zustand erhalten; bei der wiederkehrenden Prüfung und der Betreiberkontrolle erneut prüfen [O] | H36: Auffangregel (Mechanik): greift, wenn keine Mangelregel zutrifft und alle Pflichtfragen beantwortet sind. | I36: offen (Auffang) | L36: =IF(J36<>"",J36,IF($J$32="Freigeben","Freigeben",""))
A37: Gefährdung | B37: MF-M07 | D37: Fehlender, nicht abschließbarer oder nicht gekennzeichneter Hauptschalter Faktor: Elektrische Gefährdung durch Berühren spannungsführender Teile Betroffen: Wartungspersonal Bewertungslogik: Höchste Stufe – alle zutreffenden Regeln zählen, maßgeblich ist die HÖCHSTE STUFE; Maßnahmen aller Treffer werden übernommen. Bewertet, wenn: immer Pflichtfragen: 5.51, 5.51a (wenn [5.51] = Ja), 5.51b (wenn [5.51] = Ja) | H37: EN 81-80: Nr. 68 (5.13.3) DIN EN 81-20 5.10.5.1 DGUV Vorschrift 3 TRBS 3121 Anh. 1 Nr. 21 (Schutz gegen elektrischen Schlag und Kennzeichnung) | I37: 3 von 4 offen
A38: Regel | B38: MF-M07-R1 | C38: 100 | D38: [5.51 Hauptschalter vorhanden und Wirkung nachvollziehbar?] = Nein | E38: Hoch | F38: • Arbeiten nur nach Freischalten durch eine Elektrofachkraft [O] | G38: • Hauptschalter nach DIN EN 81-20 nachrüsten [T] | I38: offen | L38: =IF(J38<>"",J38,IF($J$37="Freigeben","Freigeben",""))
A39: Regel | B39: MF-M07-R2 | C39: 100 | D39: [5.51a Hauptschalter abschließbar?] = Nein | E39: Hoch | F39: • Andere Maßnahme zum Schutz gegen Wiedereinschalten anwenden [O] | G39: • Abschließbaren Hauptschalter nachrüsten [T] | H39: Entschieden 2026-09-02: K-M02. | I39: freigegeben
A40: Regel | B40: MF-M07-R3 | C40: 100 | D40: [5.51b Hauptschalter eindeutig gekennzeichnet?] = Nein | E40: Mittel | F40: • Provisorisch kennzeichnen [O] | G40: • Dauerhafte Kennzeichnung anbringen [O] | I40: offen | L40: =IF(J40<>"",J40,IF($J$37="Freigeben","Freigeben",""))
...

Sheet T Türen
A1: Art | B1: Code | C1: Prio | D1: Gefährdung / Bedingung | E1: Stufe | F1: Sofortmaßnahme | G1: Mittelfristige Maßnahme | H1: Hinweis / Quelle | I1: Status | J1: Entscheidung | K1: Korrektur | L1: wirksam
A2: Gefährdung | B2: MF-T01 | D2: Unsichere Verriegelung der Schachttüren Faktor: Mechanische Gefährdung durch Absturz in den Schacht Betroffen: Nutzer Bewertungslogik: Höchste Stufe – alle zutreffenden Regeln zählen, maßgeblich ist die HÖCHSTE STUFE; Maßnahmen aller Treffer werden übernommen. Bewertet, wenn: immer Pflichtfragen: 7.1, 7.2 | H2: EN 81-80: Nr. 31 (5.7.7), Nr. 33 (5.7.8.2) DIN EN 81-20 5.3.9.1 TRBS 3121 Anh. 1 Nr. 11 (Schachttürverriegelung) | I2: 3 von 3 offen
A3: Regel | B3: MF-T01-R1 | C3: 100 | D3: [7.1 Schachttürverriegelung vom Sicherheitskreis elektrisch überwacht?] = Nein | E3: Hoch | F3: • Aufzug ausschalten und sichern [O] | G3: • Ersatz aller Schachttür-Verriegelungen durch normgerechte Verriegelungen [T] | I3: offen | L3: =IF(J3<>"",J3,IF($J$2="Freigeben","Freigeben",""))
A4: Regel | B4: MF-T01-R2 | C4: 100 | D4: [7.2 Fehlschließsicherung / Nachschließeinrichtung an den Schachttüren vorhanden?] = Nein | E4: Mittel | F4: • Schließ- und Verriegelungsfunktion aller Schachttüren prüfen; Beauftragte Person auf offen stehende Schachttüren hinweisen [O] | G4: • Riegel mit Fehlschließeinrichtung nachrüsten [T] | H4: [Prüfbericht: H11 – Sofortmaßnahme ergänzt] | I4: offen – geändert (Rev. 2) | L4: =IF(J4<>"",J4,IF($J$2="Freigeben","Freigeben",""))
A5: Regel | B5: MF-T01-R3 | C5: 1 | D5: [7.1 Schachttürverriegelung vom Sicherheitskreis elektrisch überwacht?] ist beantwortet | E5: Kein Risiko | F5: • Zustand erhalten; bei der wiederkehrenden Prüfung und der Betreiberkontrolle erneut prüfen [O] | H5: Auffangregel (Mechanik): greift, wenn keine Mangelregel zutrifft und alle Pflichtfragen beantwortet sind. | I5: offen (Auffang) | L5: =IF(J5<>"",J5,IF($J$2="Freigeben","Freigeben",""))
A6: Gefährdung | B6: MF-T02 | D6: Fehlende oder schlecht erreichbare Notentriegelung der Schachttüren Faktor: Sonstige Gefährdung durch fehlende oder unzureichende Notfallorganisation Betroffen: Nutzer, Beauftragte Person Bewertungslogik: Höchste Stufe – alle zutreffenden Regeln zählen, maßgeblich ist die HÖCHSTE STUFE; Maßnahmen aller Treffer werden übernommen. Bewertet, wenn: immer Pflichtfragen: 7.5, 7.6, 7.7 (wenn [7.5] = Ja) | H6: EN 81-80: Nr. 32 (5.7.8.1) DIN EN 81-20 5.3.9.3 TRBS 3121 Anh. 1 Nr. 11 (Schachttürverriegelung) | I6: 4 von 4 offen
A7: Regel | B7: MF-T02-R1 | C7: 100 | D7: [7.6 Passender Entriegelungsschlüssel (Dreikant) für die Personenbefreiung vor Ort hinterlegt?] = Nein | E7: Hoch | F7: • Entriegelungsschlüssel beschaffen und an der Anlage (Schlüsseltresor) hinterlegen [O] | G7: • Schlüsselverwaltung für die Personenbefreiung in der Betriebsanweisung regeln [O] | H7: Evidenz: abgeleitet | I7: offen | L7: =IF(J7<>"",J7,IF($J$6="Freigeben","Freigeben",""))
A8: Regel | B8: MF-T02-R2 | C8: 100 | D8: [7.5 Notentriegelung an allen Schachttüren vorhanden?] = Nein | E8: Hoch | F8: • Personenbefreiung bis zur Nachrüstung nur durch das Aufzugsfachunternehmen; betroffene Haltestellen im Notfallplan kennzeichnen [O] | G8: • Notentriegelungen nachrüsten [T] | H8: [Prüfbericht: H11 – Sofortmaßnahme ergänzt] Frühere Klärung (vor der Änderung entschieden): K-K06 | I8: offen – geändert (Rev. 2) | L8: =IF(J8<>"",J8,IF($J$6="Freigeben","Freigeben",""))
A9: Regel | B9: MF-T02-R3 | C9: 100 | D9: [7.7 Notentriegelung erreichbar (max. 2,00 m über Boden im Türblatt bzw. 2,70 m im Rahmen mit langem Schlüssel)?] = Nein | E9: Mittel | F9: • Leiter/Tritt für die Personenbefreiung bereithalten, Beauftragte unterweisen [O] | G9: • Notentriegelung in erreichbarer Höhe (max. 2,00 m) nachrüsten oder langen Entriegelungsschlüssel hinterlegen [T] | H9: Evidenz: abgeleitet | I9: offen | L9: =IF(J9<>"",J9,IF($J$6="Freigeben","Freigeben",""))
A10: Regel | B10: MF-T02-R4 | C10: 1 | D10: [7.5 Notentriegelung an allen Schachttüren vorhanden?] ist beantwortet | E10: Kein Risiko | F10: • Zustand erhalten; bei der wiederkehrenden Prüfung und der Betreiberkontrolle erneut prüfen [O] | H10: Auffangregel (Mechanik): greift, wenn keine Mangelregel zutrifft und alle Pflichtfragen beantwortet sind. | I10: offen (Auffang) | L10: =IF(J10<>"",J10,IF($J$6="Freigeben","Freigeben",""))
A11: Gefährdung | B11: MF-T03 | D11: Schachttüren nicht selbstschließend Faktor: Mechanische Gefährdung durch Absturz in den Schacht Betroffen: Nutzer Bewertungslogik: Höchste Stufe – alle zutreffenden Regeln zählen, maßgeblich ist die HÖCHSTE STUFE; Maßnahmen aller Treffer werden übernommen. Bewertet, wenn: immer Pflichtfragen: 7.3, 7.4 | H11: EN 81-80: Nr. 34 (5.7.9) DIN EN 81-20 5.3.9.3.4 TRBS 3121 Anh. 1 Nr. 12 (Selbstschließung von Schiebetüren) | I11: 3 von 3 offen
A12: Regel | B12: MF-T03-R1 | C12: 100 | D12: [7.4 Schließt die Schachttür nach einer Notentriegelung selbsttätig?] = Nein | E12: Hoch | F12: • Nach jeder Notentriegelung Schachttür von Hand schließen und Verriegelung prüfen; Personenbefreiung nur durch unterwiesene Personen [O] | G12: • Schachttür umrüsten [T] | H12: [Prüfbericht: H11 – Sofortmaßnahme ergänzt] | I12: offen – geändert (Rev. 2) | L12: =IF(J12<>"",J12,IF($J$11="Freigeben","Freigeben",""))
A13: Regel | B13: MF-T03-R2 | C13: 100 | D13: [7.3 Schachttüren selbstschließend (Feder oder Gewicht)?] = Nein | E13: Mittel | F13: • Schachttüren nach jeder Personenbefreiung auf Schließ- und Verriegelungsstellung prüfen; Beauftragte Person entsprechend unterweisen [O] | G13: • Selbstschließung nachrüsten [T] | H13: [Prüfbericht 16.09.2026: konkrete Sofortmaßnahme statt „Vorsicht“] | I13: offen – geändert (Rev. 2) | L13: =IF(J13<>"",J13,IF($J$11="Freigeben","Freigeben",""))
